// fulfilled promise
new Promise((resolve, reject) => {
    console.log('resolve executor');
    resolve('success!');
})
    .then((val) => console.log('resolved: ' + val))
    .catch((val) => console.log('rejected: ' + val));

// rejected promise
new Promise((resolve, reject) => {
    console.log('reject executor');
    reject('no success :(');
})
    .then((val) => console.log('resolved: ' + val))
    .catch((val) => console.log('rejected: ' + val));

// error in promise
new Promise(() => {
    null();
})
    .then((val) => console.log('resolved: ' + val))
    .catch((val) => console.log('rejected: ' + val));

console.log('= =  the call stack is empty  = =');
